<?xml version="1.0"?>
<robot xmlns:xacro="http://ros.org/wiki/xacro">
	<include filename="$(find amr-ros-config)/urdf/materials.xacro"/>
	<xacro:macro name="pioneer3dx" params="prefix parent *origin">
		<xacro:include filename="$(find amr-ros-config)/urdf/pioneer3dx/pioneer3dx_wheel.xacro"/>

		<!-- Base Link -->
		<link name="${prefix}base_link">
			<inertial>
				<mass value="3.5"/>
				<origin xyz="0 0 0"/>
				<inertia ixx="1" ixy="0" ixz="0" iyy="1" iyz="0" izz="1"/>
			</inertial>
			<visual>
				<origin xyz="-0.045 0 0.148" rpy="0 0 0"/>
				<geometry>
					<mesh filename="package://amr-ros-config/meshes/p3dx_meshes/chassis.stl"/>
				</geometry>
				<material name="ChassisRed">
					<color rgba="0.851 0.0 0.0 1.0"/>
				</material>
			</visual>
			<collision>
				<origin xyz="0 0 0" rpy="0 0 0"/>
				<geometry>
					<box size="0.01 0.01 0.01"/>
				</geometry>
			</collision>
		</link>

		<!-- Connect to parent -->
		<joint name="${prefix}base_joint" type="fixed">
			<xacro:insert_block name="origin"/>
			<parent link="${parent}"/>
			<child link="${prefix}base_link"/>
		</joint>

		<!-- Top Plate -->
		<link name="${prefix}top_plate">
			<inertial>
				<mass value="0.01"/>	
				<origin xyz="0 0 0"/>
				<inertia ixx="1" ixy="0" ixz="0" iyy="1" iyz="0" izz="1"/>
			</inertial>
			<visual>
				<origin xyz="0 0 0" rpy="0 0 0"/>
				<geometry>
					<mesh filename="package://amr-ros-config/meshes/p3dx_meshes/top.stl"/>
				</geometry>
				<material name="TopBlack">
					<color rgba="0.038 0.038 0.038 1.0"/>
				</material>
			</visual>
		</link>

		<gazebo reference="${prefix}top_plate">
			<material>Gazebo/Black</material>
		</gazebo>

		<joint name="${prefix}base_top_joint" type="fixed">
			<origin xyz="-0.045 0 0.234" rpy="0 0 0"/>
			<parent link="${prefix}base_link"/>
			<child link="${prefix}top_plate"/>
		</joint>

		<!-- Front Sonar -->
		<link name="${prefix}front_sonar">
			<inertial>
				<mass value="0.0001"/>	
				<origin xyz="0 0 0"/>
				<inertia ixx="1" ixy="0" ixz="0" iyy="1" iyz="0" izz="1"/>
			</inertial>
			<visual>
				<origin xyz="0 0 0" rpy="0 0 0"/>
				<geometry>
					<mesh filename="package://amr-ros-config/meshes/p3dx_meshes/front_sonar.stl"/>
				</geometry>
				<material name="SonarYellow">
					<color rgba="0.715 0.583 0.210 1.0"/>
				</material>
			</visual>
		</link>

		<gazebo reference="${prefix}front_sonar">
			<material value="Gazebo/Yellow"/>
		</gazebo>

		<joint name="${prefix}base_front_joint" type="fixed">
			<origin xyz="-0.198 0 0.208" rpy="0 0 0"/>
			<parent link="${prefix}base_link"/>
			<child link="${prefix}front_sonar"/>
		</joint>

		<!-- Back Sonar -->
		<joint name="${prefix}base_back_joint" type="fixed">
			<origin xyz="0.109 0 0.209" rpy="0 0 0"/>
			<parent link="${prefix}base_link"/>
			<child link="${prefix}back_sonar"/>
		</joint>

		<link name="${prefix}back_sonar">
			<inertial>
				<mass value="0.0001"/>	
				<origin xyz="0 0 0"/>
				<inertia ixx="1" ixy="0" ixz="0" iyy="1" iyz="0" izz="1"/>
			</inertial>
			<visual>
				<origin xyz="0 0 0" rpy="0 0 0"/>
				<geometry>
					<mesh filename="package://amr-ros-config/meshes/p3dx_meshes/back_sonar.stl"/>
				</geometry>
				<material name="SonarYellow">
					<color rgba="0.715 0.583 0.210 1.0"/>
				</material>
			</visual>
		</link>

		<!-- Caster Swivel -->
		<joint name="${prefix}base_caster_swivel_joint" type="continuous">
			<origin xyz="-0.185 0 0.055" rpy="0 0 0"/>
			<axis xyz="0 0 1"/>
			<parent link="${prefix}base_link"/>
			<child link="${prefix}caster_swivel"/>
		</joint>

		<link name="${prefix}caster_swivel">
			<inertial>
				<mass value="0.1"/>	
				<origin xyz="0 0 0"/>
				<inertia ixx="0.01" ixy="0" ixz="0" iyy="0.01" iyz="0" izz="0.01"/>
			</inertial>
			<visual>
				<origin xyz="0 0 0" rpy="0 0 0"/>
				<geometry>
					<mesh filename="package://amr-ros-config/meshes/p3dx_meshes/caster_swivel.stl"/>
				</geometry>
				<material name="caster_swivel">
					<color rgba="0.5 0.5 0.5 1"/>
				</material>
			</visual>
		</link>

		<gazebo reference="${prefix}caster_swivel">
			<material value="Gazebo/Grey"/>
		</gazebo>

		<!-- Center Wheel + Hubcap -->
		<link name="${prefix}caster_hubcap">
			<inertial>
				<mass value="0.01"/>	
				<origin xyz="0 0 0"/>
				<inertia ixx="0.012411765597" ixy="-0.000711733678" ixz="0.00050272983"
								 iyy="0.015218160428" iyz="-0.000004273467" izz="0.011763977943"/>
			</inertial>
			<visual>
				<origin xyz="0 0 0" rpy="0 0 0"/>
				<geometry>
					<mesh filename="package://amr-ros-config/meshes/p3dx_meshes/caster_hubcap.stl"/>
				</geometry>
				<material name="caster_swivel">
					<color rgba="0.5 0.5 0.5 1"/>
				</material>
			</visual>
			<collision>
				<origin xyz="0 0 0" rpy="0 0 0"/>
				<geometry>
					<box size="0.05 0.05 0.05"/>
				</geometry>
			</collision>
		</link>

		<gazebo reference="${prefix}caster_hubcap">
			<material value="Gazebo/Grey"/>
		</gazebo>

		<!-- Caster Wheel -->
		<joint name="${prefix}caster_swivel_hubcap_joint" type="continuous">
			<origin xyz="-0.026 0 -0.016" rpy="1.5708 0 0"/>
			<axis xyz="0 0 1"/>
			<parent link="${prefix}caster_swivel"/>
			<child link="${prefix}caster_wheel"/>
		</joint>
		
		<link name="${prefix}caster_wheel">
			<inertial>
				<mass value="0.1"/>	
				<origin xyz="0 0 0"/>
				<inertia ixx="0.012411765597" ixy="-0.000711733678" ixz="0.00050272983"
						 iyy="0.015218160428" iyz="-0.000004273467" izz="0.011763977943"/>
				</inertial>
			<visual>
				<origin xyz="0 0 0" rpy="0 0 0"/>
				<geometry>
					<cylinder radius="0.0375" length="0.01"/>
				</geometry>
				<material name="WheelBlack">
					<color rgba="0.117 0.117 0.117 1"/>
				</material>
			</visual>
			<collision>
				<origin xyz="0 0 0" rpy="-1.5708 0 0"/>
				<geometry>
					<cylinder radius="0.0375" length="0.01"/>
				</geometry>
			</collision>
		</link>

		<joint name="${prefix}caster_wheel_joint" type="fixed">
			<origin xyz="-0.0035 0 -0.001" rpy="1.5708 0 0"/>
			<axis xyz="0 0 1"/>
			<parent link="${prefix}caster_wheel"/>
			<child link="${prefix}caster_hubcap"/>
		</joint>

		<!-- Left Wheel -->
		<link name="${prefix}left_hub">
			<visual>
				<origin xyz="0 0 0" rpy="${-3.1415927/2.0} 0 0"/>
				<geometry>
					<cylinder radius="0.09" length="0.01"/>
				</geometry>
				<material name="HubcapYellow">
					<color rgba="1.0 0.811 0.151 1.0"/>
				</material>
			</visual>
			<collision>
				<origin xyz="0 0 0" rpy="${-3.1415927/2.0} 0 0"/>
				<geometry>
					<cylinder radius="0.09" length="0.01"/>
				</geometry>
			</collision>
		</link>

		<joint name="${prefix}left_hub_joint" type="fixed">
			<origin xyz="0 0.15 0.08" rpy="0 0 0"/>
			<parent link="${prefix}base_link"/>
			<child link="${prefix}left_hub"/>
			<axis xyz="0 1 0"/>
		</joint>

		<link name="${prefix}left_wheel">
			<visual>
				<origin xyz="0 0 0" rpy="1.5708 0 0"/>
				<geometry>
					<mesh filename="package://amr-ros-config/meshes/p3dx_meshes/left_wheel.stl"/>
				</geometry>
				<material name="WheelBlack">
					<color rgba="0.117 0.117 0.117 1"/>
				</material>
			</visual>
		</link>

		<joint name="${prefix}left_wheel_joint" type="continuous">
			<origin xyz="0 0 0" rpy="-1.5708 0 0"/>
			<axis xyz="0 0 1"/>
			<parent link="${prefix}left_hub"/>
			<child link="${prefix}left_wheel"/>
		</joint>
	
		<gazebo reference="${prefix}left_wheel_joint">
			<material value="Gazebo/Black"/>
		</gazebo>

		<!-- Right Wheel -->
		<link name="${prefix}right_hub">
			<visual>
				<origin xyz="0 0 0" rpy="${-3.1415927/2.0} 0 0"/>
				<geometry>
					<cylinder radius="0.09" length="0.01"/>
				</geometry>
				<material name="HubcapYellow">
					<color rgba="1.0 0.811 0.151 1.0"/>
				</material>
			</visual>
			<collision>
				<origin xyz="0 0 0" rpy="${-3.1415927/2.0} 0 0"/>
				<geometry>
					<cylinder radius="0.09" length="0.01"/>
				</geometry>
			</collision>
		</link>
		<gazebo reference="${prefix}right_hub">
			<material value="Gazebo/Yellow"/>
		</gazebo>

		<joint name="${prefix}right_hub_joint" type="fixed">
			<origin xyz="0 -0.15 0.08" rpy="0 0 0"/>
			<parent link="${prefix}base_link"/>
			<child link="${prefix}right_hub"/>
		</joint>

		<link name="${prefix}right_wheel">
			<visual>
				<origin xyz="0 0 0" rpy="-1.5708 0 0"/>
				<geometry>
					<mesh filename="package://amr-ros-config/meshes/p3dx_meshes/right_wheel.stl"/>
				</geometry>
				<material name="WheelBlack">
					<color rgba="0.117 0.117 0.117 1"/>
				</material>
			</visual>
		</link>

		<joint name="${prefix}right_wheel_joint" type="continuous">
			<origin xyz="0 0 0" rpy="1.5708 0 0"/>
			<axis xyz="0 0 1"/>
			<parent link="${prefix}right_hub"/>
			<child link="${prefix}right_wheel"/>
		</joint>

		<gazebo reference="${prefix}right_wheel_joint">
			<material value="Gazebo/Black"/>
		</gazebo>

		<!-- Gazebo plugin -->
		<gazebo>
			<plugin name="differential_drive_controller" filename="libgazebo_ros_diff_drive.so">
				<alwaysOn>true</alwaysOn>
				<updateRate>100</updateRate>
				<leftJoint>${prefix}left_wheel_joint</leftJoint>
				<rightJoint>${prefix}right_wheel_joint</rightJoint>
				<wheelSeparation>0.3</wheelSeparation>
				<wheelDiameter>0.12</wheelDiameter>
				<torque>5</torque>
				<commandTopic>cmd_vel</commandTopic>
				<robotBaseFrame>${prefix}base_link</robotBaseFrame>
				<odometryTopic>odom</odometryTopic>
				<odometryFrame>odom</odometryFrame>
			</plugin>
		</gazebo>

	</xacro:macro>

</robot>
